Workbook

Sheet Summary
A1: DevPulse AI - Restart Task Tracker
A2: Source: docs/project-restart/TASK_BACKLOG.md (2026-10-21). Every number below is a formula over the Tasks sheet.
A4: Milestone | B4: Tasks | C4: Done | D4: In Progress | E4: Blocked | F4: Not Started | G4: % Done | H4: Est. Hours | I4: Remaining Hours | J4: Open P0
A5: M0 - Recovery & local dev | B5: =COUNTIF(Tasks!$B$2:$B$82,$A5) | C5: =COUNTIFS(Tasks!$B$2:$B$82,$A5,Tasks!$I$2:$I$82,"Done") | D5: =COUNTIFS(Tasks!$B$2:$B$82,$A5,Tasks!$I$2:$I$82,"In progress") | E5: =COUNTIFS(Tasks!$B$2:$B$82,$A5,Tasks!$I$2:$I$82,"Blocked") | F5: =COUNTIFS(Tasks!$B$2:$B$82,$A5,Tasks!$I$2:$I$82,"Not started") | G5: =IF(B5=0,0,C5/B5) | H5: =SUMIF(Tasks!$B$2:$B$82,$A5,Tasks!$G$2:$G$82) | I5: =SUMIFS(Tasks!$G$2:$G$82,Tasks!$B$2:$B$82,$A5,Tasks!$I$2:$I$82,"<>Done") | J5: =COUNTIFS(Tasks!$B$2:$B$82,$A5,Tasks!$E$2:$E$82,"P0",Tasks!$I$2:$I$82,"<>Done")
A6: M1 - Backend stabilization & security | B6: =COUNTIF(Tasks!$B$2:$B$82,$A6) | C6: =COUNTIFS(Tasks!$B$2:$B$82,$A6,Tasks!$I$2:$I$82,"Done") | D6: =COUNTIFS(Tasks!$B$2:$B$82,$A6,Tasks!$I$2:$I$82,"In progress") | E6: =COUNTIFS(Tasks!$B$2:$B$82,$A6,Tasks!$I$2:$I$82,"Blocked") | F6: =COUNTIFS(Tasks!$B$2:$B$82,$A6,Tasks!$I$2:$I$82,"Not started") | G6: =IF(B6=0,0,C6/B6) | H6: =SUMIF(Tasks!$B$2:$B$82,$A6,Tasks!$G$2:$G$82) | I6: =SUMIFS(Tasks!$G$2:$G$82,Tasks!$B$2:$B$82,$A6,Tasks!$I$2:$I$82,"<>Done") | J6: =COUNTIFS(Tasks!$B$2:$B$82,$A6,Tasks!$E$2:$E$82,"P0",Tasks!$I$2:$I$82,"<>Done")
A7: M2 - Frontend foundation + auth | B7: =COUNTIF(Tasks!$B$2:$B$82,$A7) | C7: =COUNTIFS(Tasks!$B$2:$B$82,$A7,Tasks!$I$2:$I$82,"Done") | D7: =COUNTIFS(Tasks!$B$2:$B$82,$A7,Tasks!$I$2:$I$82,"In progress") | E7: =COUNTIFS(Tasks!$B$2:$B$82,$A7,Tasks!$I$2:$I$82,"Blocked") | F7: =COUNTIFS(Tasks!$B$2:$B$82,$A7,Tasks!$I$2:$I$82,"Not started") | G7: =IF(B7=0,0,C7/B7) | H7: =SUMIF(Tasks!$B$2:$B$82,$A7,Tasks!$G$2:$G$82) | I7: =SUMIFS(Tasks!$G$2:$G$82,Tasks!$B$2:$B$82,$A7,Tasks!$I$2:$I$82,"<>Done") | J7: =COUNTIFS(Tasks!$B$2:$B$82,$A7,Tasks!$E$2:$E$82,"P0",Tasks!$I$2:$I$82,"<>Done")
A8: M3 - GitHub connect, repos & PRs | B8: =COUNTIF(Tasks!$B$2:$B$82,$A8) | C8: =COUNTIFS(Tasks!$B$2:$B$82,$A8,Tasks!$I$2:$I$82,"Done") | D8: =COUNTIFS(Tasks!$B$2:$B$82,$A8,Tasks!$I$2:$I$82,"In progress") | E8: =COUNTIFS(Tasks!$B$2:$B$82,$A8,Tasks!$I$2:$I$82,"Blocked") | F8: =COUNTIFS(Tasks!$B$2:$B$82,$A8,Tasks!$I$2:$I$82,"Not started") | G8: =IF(B8=0,0,C8/B8) | H8: =SUMIF(Tasks!$B$2:$B$82,$A8,Tasks!$G$2:$G$82) | I8: =SUMIFS(Tasks!$G$2:$G$82,Tasks!$B$2:$B$82,$A8,Tasks!$I$2:$I$82,"<>Done") | J8: =COUNTIFS(Tasks!$B$2:$B$82,$A8,Tasks!$E$2:$E$82,"P0",Tasks!$I$2:$I$82,"<>Done")
A9: M4 - AI review engine | B9: =COUNTIF(Tasks!$B$2:$B$82,$A9) | C9: =COUNTIFS(Tasks!$B$2:$B$82,$A9,Tasks!$I$2:$I$82,"Done") | D9: =COUNTIFS(Tasks!$B$2:$B$82,$A9,Tasks!$I$2:$I$82,"In progress") | E9: =COUNTIFS(Tasks!$B$2:$B$82,$A9,Tasks!$I$2:$I$82,"Blocked") | F9: =COUNTIFS(Tasks!$B$2:$B$82,$A9,Tasks!$I$2:$I$82,"Not started") | G9: =IF(B9=0,0,C9/B9) | H9: =SUMIF(Tasks!$B$2:$B$82,$A9,Tasks!$G$2:$G$82) | I9: =SUMIFS(Tasks!$G$2:$G$82,Tasks!$B$2:$B$82,$A9,Tasks!$I$2:$I$82,"<>Done") | J9: =COUNTIFS(Tasks!$B$2:$B$82,$A9,Tasks!$E$2:$E$82,"P0",Tasks!$I$2:$I$82,"<>Done")
A10: M5 - Webhooks & inline comments | B10: =COUNTIF(Tasks!$B$2:$B$82,$A10) | C10: =COUNTIFS(Tasks!$B$2:$B$82,$A10,Tasks!$I$2:$I$82,"Done") | D10: =COUNTIFS(Tasks!$B$2:$B$82,$A10,Tasks!$I$2:$I$82,"In progress") | E10: =COUNTIFS(Tasks!$B$2:$B$82,$A10,Tasks!$I$2:$I$82,"Blocked") | F10: =COUNTIFS(Tasks!$B$2:$B$82,$A10,Tasks!$I$2:$I$82,"Not started") | G10: =IF(B10=0,0,C10/B10) | H10: =SUMIF(Tasks!$B$2:$B$82,$A10,Tasks!$G$2:$G$82) | I10: =SUMIFS(Tasks!$G$2:$G$82,Tasks!$B$2:$B$82,$A10,Tasks!$I$2:$I$82,"<>Done") | J10: =COUNTIFS(Tasks!$B$2:$B$82,$A10,Tasks!$E$2:$E$82,"P0",Tasks!$I$2:$I$82,"<>Done")
A11: M6 - Indexing, search & RAG | B11: =COUNTIF(Tasks!$B$2:$B$82,$A11) | C11: =COUNTIFS(Tasks!$B$2:$B$82,$A11,Tasks!$I$2:$I$82,"Done") | D11: =COUNTIFS(Tasks!$B$2:$B$82,$A11,Tasks!$I$2:$I$82,"In progress") | E11: =COUNTIFS(Tasks!$B$2:$B$82,$A11,Tasks!$I$2:$I$82,"Blocked") | F11: =COUNTIFS(Tasks!$B$2:$B$82,$A11,Tasks!$I$2:$I$82,"Not started") | G11: =IF(B11=0,0,C11/B11) | H11: =SUMIF(Tasks!$B$2:$B$82,$A11,Tasks!$G$2:$G$82) | I11: =SUMIFS(Tasks!$G$2:$G$82,Tasks!$B$2:$B$82,$A11,Tasks!$I$2:$I$82,"<>Done") | J11: =COUNTIFS(Tasks!$B$2:$B$82,$A11,Tasks!$E$2:$E$82,"P0",Tasks!$I$2:$I$82,"<>Done")
A12: M7 - Hardening & E2E tests | B12: =COUNTIF(Tasks!$B$2:$B$82,$A12) | C12: =COUNTIFS(Tasks!$B$2:$B$82,$A12,Tasks!$I$2:$I$82,"Done") | D12: =COUNTIFS(Tasks!$B$2:$B$82,$A12,Tasks!$I$2:$I$82,"In progress") | E12: =COUNTIFS(Tasks!$B$2:$B$82,$A12,Tasks!$I$2:$I$82,"Blocked") | F12: =COUNTIFS(Tasks!$B$2:$B$82,$A12,Tasks!$I$2:$I$82,"Not started") | G12: =IF(B12=0,0,C12/B12) | H12: =SUMIF(Tasks!$B$2:$B$82,$A12,Tasks!$G$2:$G$82) | I12: =SUMIFS(Tasks!$G$2:$G$82,Tasks!$B$2:$B$82,$A12,Tasks!$I$2:$I$82,"<>Done") | J12: =COUNTIFS(Tasks!$B$2:$B$82,$A12,Tasks!$E$2:$E$82,"P0",Tasks!$I$2:$I$82,"<>Done")
A13: M8 - Deploy, CI/CD & docs | B13: =COUNTIF(Tasks!$B$2:$B$82,$A13) | C13: =COUNTIFS(Tasks!$B$2:$B$82,$A13,Tasks!$I$2:$I$82,"Done") | D13: =COUNTIFS(Tasks!$B$2:$B$82,$A13,Tasks!$I$2:$I$82,"In progress") | E13: =COUNTIFS(Tasks!$B$2:$B$82,$A13,Tasks!$I$2:$I$82,"Blocked") | F13: =COUNTIFS(Tasks!$B$2:$B$82,$A13,Tasks!$I$2:$I$82,"Not started") | G13: =IF(B13=0,0,C13/B13) | H13: =SUMIF(Tasks!$B$2:$B$82,$A13,Tasks!$G$2:$G$82) | I13: =SUMIFS(Tasks!$G$2:$G$82,Tasks!$B$2:$B$82,$A13,Tasks!$I$2:$I$82,"<>Done") | J13: =COUNTIFS(Tasks!$B$2:$B$82,$A13,Tasks!$E$2:$E$82,"P0",Tasks!$I$2:$I$82,"<>Done")
A14: Total | B14: =SUM(B5:B13) | C14: =SUM(C5:C13) | D14: =SUM(D5:D13) | E14: =SUM(E5:E13) | F14: =SUM(F5:F13) | G14: =IF(B14=0,0,C14/B14) | H14: =SUM(H5:H13) | I14: =SUM(I5:I13) | J14: =SUM(J5:J13)
A16: By priority
A17: Priority | B17: Tasks | C17: Done | D17: Remaining Hours
A18: P0 | B18: =COUNTIF(Tasks!$E$2:$E$82,$A18) | C18: =COUNTIFS(Tasks!$E$2:$E$82,$A18,Tasks!$I$2:$I$82,"Done") | D18: =SUMIFS(Tasks!$G$2:$G$82,Tasks!$E$2:$E$82,$A18,Tasks!$I$2:$I$82,"<>Done")
A19: P1 | B19: =COUNTIF(Tasks!$E$2:$E$82,$A19) | C19: =COUNTIFS(Tasks!$E$2:$E$82,$A19,Tasks!$I$2:$I$82,"Done") | D19: =SUMIFS(Tasks!$G$2:$G$82,Tasks!$E$2:$E$82,$A19,Tasks!$I$2:$I$82,"<>Done")
A20: P2 | B20: =COUNTIF(Tasks!$E$2:$E$82,$A20) | C20: =COUNTIFS(Tasks!$E$2:$E$82,$A20,Tasks!$I$2:$I$82,"Done") | D20: =SUMIFS(Tasks!$G$2:$G$82,Tasks!$E$2:$E$82,$A20,Tasks!$I$2:$I$82,"<>Done")
A23: How to use
A24: 1. Update work in the Tasks sheet: Status (dropdown), Start Date, Done Date and Notes - the yellow columns.
A25: 2. Row M0-01 is a filled-in example of a finished task. Dates are typed as YYYY-MM-DD text.
A26: 3. Summary recalculates automatically. Est. Hours come from the Effort size via the Lookups sheet.
A27: 4. Use the filter arrows on the Tasks header to view one milestone, priority or status.
A28: 5. Open decisions that affect tasks are tracked in the Decisions sheet.
A29: Hours are rough planning estimates (S=2, M=4, L=8, XL=16), not commitments.

Sheet Tasks
A1: ID | B1: Milestone | C1: Task | D1: Type | E1: Priority | F1: Effort | G1: Est. Hours | H1: Depends On | I1: Status | J1: Start Date | K1: Done Date | L1: Expected Outcome | M1: Acceptance Criteria | N1: Verification / Tests | O1: Files / APIs | P1: Notes
A2: M0-01 | B2: M0 - Recovery & local dev | C2: Remove literal secrets and rotate the JWT secret | D2: INF/BE | E2: P0 | F2: S | G2: =IFERROR(INDEX(Lookups!$B$2:$B$5,MATCH(F2,Lookups!$A$2:$A$5,0)),"") | H2: D-01 decision (whether to rewrite history). Blocks M0-04. | I2: Done | J2: 2026-10-21 | K2: 2026-10-21 | L2: no secret values in tracked files. App reads JWT_SECRET, DB_PASSWORD, etc. from the environment with no fallback defaults. | M2: git grep -nE '^(jwt\.secret|spring\.datasource\.password|spring\.ai\.openai\.api-key)=[^$]' returns nothing. A new JWT secret (≥ 256-bit) is used locally. .env.example lists every variable with placeholder values only. | N2: start the app with .env → login works. Start without JWT_SECRET → fails fast with a clear message. Run gitleaks (or similar) on HEAD. | O2: src/main/resources/application.properties, application-docker.properties, .env.example. | P2: Secrets moved to env vars + local .env generated. Uncommitted - pending your review/commit.
A3: M0-02 | B3: M0 - Recovery & local dev | C3: Confirm compile on JDK 21 | D3: BE | E3: P0 | F3: S | G3: =IFERROR(INDEX(Lookups!$B$2:$B$5,MATCH(F3,Lookups!$A$2:$A$5,0)),"") | H3: MAC_SETUP §2.1–2.2. | I3: Done | J3: 2026-10-21 | K3: 2026-10-21 | L3: ./mvnw -DskipTests compile succeeds on this Mac. Any compile blockers are fixed minimally (e.g. the S3Service package/dir mismatch, if it breaks the build). | M3: build log saved in the PR description. No behaviour changes. | N3: ./mvnw -DskipTests compile. | P3: BUILD SUCCESS: 91 files, 0 errors/warnings (Temurin 21.0.12.1, Maven 3.9.16). Fixed mvnw exec bit. Uncommitted.
A4: M0-03 | B4: M0 - Recovery & local dev | C4: Local dev compose with pgvector and Redis | D4: INF | E4: P0 | F4: M | G4: =IFERROR(INDEX(Lookups!$B$2:$B$5,MATCH(F4,Lookups!$A$2:$A$5,0)),"") | I4: Done | J4: 2026-10-21 | K4: 2026-10-21 | L4: compose.dev.yaml with pgvector/pgvector:pg17 (port 5433, named volume, healthcheck) and redis:7 (healthcheck). Backend runs from the IDE/mvnw against it. | M4: docker compose -f compose.dev.yaml up -d → both healthy. CREATE EXTENSION vector succeeds. | N4: psql -h localhost -p 5433 -U devpulse -c "select extversion from pg_extension where extname='vector'", redis-cli ping. | O4: new compose.dev.yaml; keep compose.yaml for the containerized backend. | P4: compose.dev.yaml: Postgres 17.11 + pgvector 0.8.7 on 127.0.0.1:5433, Redis on 127.0.0.1:6379, both healthy. Uncommitted.
A5: M0-04 | B5: M0 - Recovery & local dev | C5: Fix profiles and environment mapping | D5: INF/BE | E5: P0 | F5: M | G5: =IFERROR(INDEX(Lookups!$B$2:$B$5,MATCH(F5,Lookups!$A$2:$A$5,0)),"") | H5: M0-01, M0-03. | I5: Done | J5: 2026-10-21 | K5: 2026-10-21 | L5: profiles local (default for dev), docker, prod. Datasource URL is built from DB_HOST/DB_PORT/DB_NAME. Redis uses REDIS_HOST/REDIS_PORT (fixes the devpulse-redis vs redis mismatch). Bucket/region come from env. show-sql is off by default. | M5: no hostnames or bucket names hard-coded in properties. docker compose up (backend + redis) connects to Redis. | N5: /actuator/health shows db and redis UP in both the local and docker runs. | O5: application*.properties, compose.yaml, S3Config.java, .env.example. | P5: Hosts/ports/bucket/region from env; docker Redis host fixed. Verified: local run + docker run both health UP (db, redis). Uncommitted.
A6: M0-05 | B6: M0 - Recovery & local dev | C6: Take the ONNX model out of Git and the image | D6: INF/BE | E6: P1 | F6: M | G6: =IFERROR(INDEX(Lookups!$B$2:$B$5,MATCH(F6,Lookups!$A$2:$A$5,0)),"") | H6: D-06 (embedding strategy), D-01 (history rewrite to purge the blob). | I6: Done | J6: 2026-10-21 | K6: 2026-10-21 | L6: the model and tokenizer are loaded from a configurable URI (default: the Spring AI/Hugging Face URL with on-disk cache, or a path mounted in Docker). src/main/resources/embeddings/ is removed and gitignored. | M6: the repo working tree has no file over 5 MB. The image shrinks by about 90 MB. Embedding still yields 384-dim vectors. | N6: an integration test embeds a string and asserts length == 384. docker image ls size before and after. | P6: Model loaded from pinned HF revision (all-MiniLM-L6-v2 @1110a243) and cached in EMBEDDING_CACHE_DIR; embeddings/ removed. Old config crashed (ClassCastException) - now fixed. Image 1.64 GB -> 1.31 GB. Uncommitted. History still holds the 90 MB blob (D-01).
A7: M0-06 | B7: M0 - Recovery & local dev | C7: Make Flyway the schema authority | D7: BE | E7: P1 | F7: S | G7: =IFERROR(INDEX(Lookups!$B$2:$B$5,MATCH(F7,Lookups!$A$2:$A$5,0)),"") | I7: Done | J7: 2026-10-21 | K7: 2026-10-21 | L7: ddl-auto=validate in all profiles. V2__enable_pgvector.sql creates the vector extension. Spring AI initialize-schema=false once M6-01 lands (until then, keep it true and document why). | M7: an empty DB migrates cleanly and Hibernate validation passes. | N7: M0-07 integration test boots against an empty Testcontainers DB. | P7: ddl-auto=validate everywhere; V2__enable_pgvector.sql. Verified on fresh DB (Testcontainers) and existing dev DB (V2 applied, validate OK). vector_store still created by Spring AI until M6-01. Uncommitted.
A8: M0-07 | B8: M0 - Recovery & local dev | C8: Test harness: Testcontainers integration base | D8: BE | E8: P0 | F8: M | G8: =IFERROR(INDEX(Lookups!$B$2:$B$5,MATCH(F8,Lookups!$A$2:$A$5,0)),"") | H8: Docker installed, M0-04. | I8: Done | J8: 2026-10-21 | K8: 2026-10-21 | L8: spring-boot-testcontainers + testcontainers-postgresql (pgvector image) + a Redis container. An AbstractIntegrationTest with @ServiceConnection. A test profile with ai.provider=mock and the embedding model stubbed or cached. contextLoads replaced by a smoke test (health UP + register/login round trip). | M8: ./mvnw verify passes from a clean clone with only Docker running. | N8: ./mvnw verify locally (output pasted in the PR). | P8: AbstractIntegrationTest (pgvector + Redis containers, @ServiceConnection) + 3-test smoke suite; contextLoads removed. ./mvnw verify: 3 tests, 0 failures; also passes without .env. Testcontainers pinned to 1.21.4 (1.21.3 fails on Docker 29). Uncommitted.
A9: M0-08 | B9: M0 - Recovery & local dev | C9: GitHub Actions CI | D9: INF | E9: P1 | F9: S | G9: =IFERROR(INDEX(Lookups!$B$2:$B$5,MATCH(F9,Lookups!$A$2:$A$5,0)),"") | I9: In progress | J9: 2026-10-21 | L9: .github/workflows/ci.yml runs on PRs: JDK 21 setup, Maven cache, ./mvnw verify, gitleaks secret scan. A frontend job is added in M2-03. | M9: CI green on a PR. Branch protection on main requires it (you configure this in GitHub settings). | N9: the PR shows a passing check. | P9: ci.yml written (backend verify + model cache + gitleaks on HEAD with custom .gitleaks.toml rule). actionlint clean; gitleaks verified locally (catches old leak, current files clean). NOT yet run on GitHub - mark Done after the first green run. Commit must include mvnw exec bit. Branch protection is yours to enable.
A10: M1-01 | B10: M1 - Backend stabilization & security | C10: Response DTOs for repositories and pull requests | D10: BE | E10: P0 | F10: M | G10: =IFERROR(INDEX(Lookups!$B$2:$B$5,MATCH(F10,Lookups!$A$2:$A$5,0)),"") | I10: Not started | L10: RepositoryResponse, PullRequestSummaryResponse, PullRequestDetailResponse (records) plus mappers. No controller returns an entity. | M10: grep -rn "ResponseEntity<GitHubRepository>\|ResponseEntity<PullRequest>\|List<PullRequest>>" controller/ is empty. No response contains accessToken or refreshToken. | N10: MockMvc tests assert the JSON shape and the absence of token fields. | O10: GitHubRepositoryController, PullRequestController, new dto/github/*, new mapper/ package (or static factory methods).
A11: M1-02 | B11: M1 - Backend stabilization & security | C11: Ownership enforcement (fix IDOR) | D11: BE | E11: P0 | F11: M | G11: =IFERROR(INDEX(Lookups!$B$2:$B$5,MATCH(F11,Lookups!$A$2:$A$5,0)),"") | H11: M1-01. | I11: Not started | L11: every repo/PR read or delete is resolved through the authenticated user's GitHub account (e.g. findByIdAndGithubAccountUserId). Unknown or foreign IDs → 404. | M11: user B gets 404 for every endpoint using user A's IDs. The /account/{accountId} endpoint is replaced by a "mine" endpoint (M3-05) or locked down. | N11: integration tests with two users.
A12: M1-03 | B12: M1 - Backend stabilization & security | C12: Robust JWT filter + JSON 401/403 | D12: BE | E12: P0 | F12: S | G12: =IFERROR(INDEX(Lookups!$B$2:$B$5,MATCH(F12,Lookups!$A$2:$A$5,0)),"") | I12: Not started | L12: malformed, expired, bad-signature, or blacklisted tokens → request continues unauthenticated → a JSON 401 from a custom AuthenticationEntryPoint. Add a JSON AccessDeniedHandler. Logout tolerates invalid tokens. | M12: each bad-token variant returns 401 {"status":401,...}, never 500. | N12: unit tests for JwtService; MockMvc tests for each token variant. | O12: JwtAuthenticationFilter, SecurityConfig, AuthController.logout. | P12: Observed 2026-10-21: a logged-out (blacklisted) token returns 403 instead of 401.
A13: M1-04 | B13: M1 - Backend stabilization & security | C13: Complete the error contract | D13: BE | E13: P1 | F13: S | G13: =IFERROR(INDEX(Lookups!$B$2:$B$5,MATCH(F13,Lookups!$A$2:$A$5,0)),"") | I13: Not started | L13: handlers for AIServiceException (502), AccessDeniedException (403), HttpMessageNotReadable/MethodArgumentTypeMismatch/ConstraintViolation (400), and a catch-all (500, no stack trace in the body). RuntimeException("User not found") is replaced with ResourceNotFoundException. ErrorResponse gains path and optional errors[]. | M13: documented error shape used by every endpoint. | N13: MockMvc tests per handler.
A14: M1-05 | B14: M1 - Backend stabilization & security | C14: Fix the PR cache serialization | D14: BE | E14: P1 | F14: S | G14: =IFERROR(INDEX(Lookups!$B$2:$B$5,MATCH(F14,Lookups!$A$2:$A$5,0)),"") | H14: M1-01. | I14: Not started | L14: cache stores List<PullRequestSummaryResponse> with typed deserialization. The JsonNode → List<PullRequest> cast is removed. | M14: sync with PRs succeeds. Cache round-trip returns equal DTOs. | N14: integration test with a Redis container and a mocked GitHubApiClient. | O14: GitHubCacheService(Impl), PullRequestServiceImpl.
A15: M1-06 | B15: M1 - Backend stabilization & security | C15: CORS for the SPA | D15: BE | E15: P1 | F15: S | G15: =IFERROR(INDEX(Lookups!$B$2:$B$5,MATCH(F15,Lookups!$A$2:$A$5,0)),"") | I15: Not started | L15: CorsConfigurationSource driven by APP_ALLOWED_ORIGINS (default http://localhost:5173). Allows Authorization and Content-Type. | M15: a preflight from the allowed origin passes. Other origins are rejected. | N15: MockMvc preflight test; browser check in M2.
A16: M1-07 | B16: M1 - Backend stabilization & security | C16: Consistent JSON success responses | D16: BE | E16: P2 | F16: S | G16: =IFERROR(INDEX(Lookups!$B$2:$B$5,MATCH(F16,Lookups!$A$2:$A$5,0)),"") | I16: Not started | L16: register returns 201 + {id,email,name}. Password change returns 204. OAuth authorize returns {url}. | M16: no text/plain responses under /api/. | N16: MockMvc.
A17: M1-08 | B17: M1 - Backend stabilization & security | C17: Remove dead and unsafe code | D17: BE | E17: P1 | F17: S | G17: =IFERROR(INDEX(Lookups!$B$2:$B$5,MATCH(F17,Lookups!$A$2:$A$5,0)),"") | I17: Not started | L17: delete POST /api/github/connect (+ ConnectGitHubRequest, related service method), the inner AuthController.TestController, S3TestController, VectorStoreController, and unused AIChatRequest/Response. Fix the S3Service package. Keep S3Service only if D-08 says so. | M17: compile + tests pass. Endpoint list matches FEATURE_MATRIX after cleanup. | N17: ./mvnw verify; check the OpenAPI listing once M2-02 lands.
A18: M1-09 | B18: M1 - Backend stabilization & security | C18: Encrypt GitHub tokens at rest | D18: BE | E18: P1 | F18: M | G18: =IFERROR(INDEX(Lookups!$B$2:$B$5,MATCH(F18,Lookups!$A$2:$A$5,0)),"") | I18: Not started | L18: a JPA AttributeConverter with AES-GCM, key from TOKEN_ENCRYPTION_KEY (KMS later). The migration widens columns and makes refresh_token nullable (also needed by M3-01). Existing rows are re-encrypted or cleared (users reconnect). | M18: DB column values aren't plaintext tokens. The app still calls GitHub successfully. | N18: unit test for the converter; integration test reads the raw column via JDBC.
A19: M1-10 | B19: M1 - Backend stabilization & security | C19: Audit timestamps | D19: BE | E19: P2 | F19: S | G19: =IFERROR(INDEX(Lookups!$B$2:$B$5,MATCH(F19,Lookups!$A$2:$A$5,0)),"") | I19: Not started | L19: @EnableJpaAuditing + @CreatedDate/@LastModifiedDate (or Hibernate @CreationTimestamp) on BaseEntity. | M19: Expected Outcome delivered and all Verification checks pass. | N19: an integration test asserts non-null createdAt/updatedAt after save/update.
A20: M2-01 | B20: M2 - Frontend foundation + auth | C20: GET /api/auth/me | D20: BE | E20: P0 | F20: S | G20: =IFERROR(INDEX(Lookups!$B$2:$B$5,MATCH(F20,Lookups!$A$2:$A$5,0)),"") | I20: Not started | L20: returns {id,name,email,role,github:{connected,username,avatarUrl}}, read from the DB. /api/profile GET stays as an alias, or is deprecated. | M20: Expected Outcome delivered and all Verification checks pass. | N20: MockMvc with and without a GitHub account.
A21: M2-02 | B21: M2 - Frontend foundation + auth | C21: OpenAPI documentation | D21: BE | E21: P1 | F21: S | G21: =IFERROR(INDEX(Lookups!$B$2:$B$5,MATCH(F21,Lookups!$A$2:$A$5,0)),"") | I21: Not started | L21: springdoc-openapi-starter-webmvc-ui. /v3/api-docs and /swagger-ui are public in local/dev only. A Bearer security scheme is declared. | M21: Expected Outcome delivered and all Verification checks pass. | N21: Swagger UI lists every endpoint. In the prod profile, the docs return 404.
A22: M2-03 | B22: M2 - Frontend foundation + auth | C22: Scaffold the React app | D22: FE | E22: P0 | F22: M | G22: =IFERROR(INDEX(Lookups!$B$2:$B$5,MATCH(F22,Lookups!$A$2:$A$5,0)),"") | H22: D-04 (repo layout), D-11 (stack). | I22: Not started | L22: frontend/ with Vite + React + TypeScript (strict), ESLint + Prettier, Vitest + React Testing Library, MSW for API mocks, path aliases, .env.example (VITE_API_BASE_URL), and a CI job (lint, typecheck, test, build). | M22: Expected Outcome delivered and all Verification checks pass. | N22: npm run lint && npm run typecheck && npm test && npm run build in CI. | O22: src/app (router, providers), src/features/<feature>/{api,components,pages,hooks}, src/components/ui (design system), src/lib (api client, utils), src/types (generated from OpenAPI).
A23: M2-04 | B23: M2 - Frontend foundation + auth | C23: Auth flows | D23: FS | E23: P0 | F23: L | G23: =IFERROR(INDEX(Lookups!$B$2:$B$5,MATCH(F23,Lookups!$A$2:$A$5,0)),"") | H23: M1-03, M1-06, M2-01, M2-03. | I23: Not started | L23: /login and /register pages (react-hook-form + zod mirroring backend validation), API client with Bearer injection and a 401 interceptor → logout + redirect, auth store (per D-05), <RequireAuth> route guard, session bootstrap via /api/auth/me, logout. | M23: field-level server errors are shown (409 duplicate email, 401 bad credentials). A refresh keeps the session. An expired token redirects to login. | N23: RTL tests with MSW; a manual check against the real backend.
A24: M2-05 | B24: M2 - Frontend foundation + auth | C24: App shell and design system | D24: FE | E24: P0 | F24: L | G24: =IFERROR(INDEX(Lookups!$B$2:$B$5,MATCH(F24,Lookups!$A$2:$A$5,0)),"") | I24: Not started | L24: responsive layout (sidebar + topbar, mobile drawer), light/dark theme, and shared components: Button, Input, Select, Card, Badge (severity colours), Table, Tabs, Dialog, Toast, Skeleton, EmptyState, ErrorState (with retry), Pagination, CodeBlock. NotFound page and error boundary. | M24: works at 360 px width with no horizontal scroll. Keyboard navigable. Colour contrast AA. | N24: Vitest component tests; a manual viewport check.
A25: M2-06 | B25: M2 - Frontend foundation + auth | C25: Settings: profile and password | D25: FE | E25: P1 | F25: M | G25: =IFERROR(INDEX(Lookups!$B$2:$B$5,MATCH(F25,Lookups!$A$2:$A$5,0)),"") | I25: Not started | L25: /settings/profile (update name/email), /settings/security (change password). Success toasts and server-side validation errors. | M25: Expected Outcome delivered and all Verification checks pass. | N25: RTL tests; manual E2E. | O25: PUT /api/profile, PUT /api/profile/password.
A26: M2-07 | B26: M2 - Frontend foundation + auth | C26: Playwright E2E: auth journey | D26: FE/INF | E26: P1 | F26: M | G26: =IFERROR(INDEX(Lookups!$B$2:$B$5,MATCH(F26,Lookups!$A$2:$A$5,0)),"") | I26: Not started | L26: Playwright project against compose (backend + DB + Redis) covering register → login → dashboard shell → profile update → logout → guard redirect. | M26: Expected Outcome delivered and all Verification checks pass. | N26: passes locally and in CI (nightly or on PR).
A27: M3-01 | B27: M3 - GitHub connect, repos & PRs | C27: Correct the OAuth authorize and token handling | D27: BE | E27: P0 | F27: M | G27: =IFERROR(INDEX(Lookups!$B$2:$B$5,MATCH(F27,Lookups!$A$2:$A$5,0)),"") | H27: D-02, M1-09 (nullable refresh column). | I27: Not started | L27: authorize URL built with UriComponentsBuilder (encoded), includes scope (OAuth App: repo read:user; GitHub App: none). Token exchange handles the error field, missing expires_in (non-expiring), and a null refresh_token. GitHubTokenService only refreshes when expiry is known. | M27: Expected Outcome delivered and all Verification checks pass. | N27: unit tests with WireMock covering expiring and non-expiring token responses plus an error response.
A28: M3-02 | B28: M3 - GitHub connect, repos & PRs | C28: Callback redirects to the SPA | D28: BE | E28: P0 | F28: S | G28: =IFERROR(INDEX(Lookups!$B$2:$B$5,MATCH(F28,Lookups!$A$2:$A$5,0)),"") | I28: Not started | L28: the callback returns 302 to ${APP_FRONTEND_URL}/github/callback?status=success|error&reason=…. No tokens in the URL. | M28: Expected Outcome delivered and all Verification checks pass. | N28: MockMvc asserts the Location header for success and for invalid state.
A29: M3-03 | B29: M3 - GitHub connect, repos & PRs | C29: Connection status + disconnect with revocation | D29: BE | E29: P0 | F29: S | G29: =IFERROR(INDEX(Lookups!$B$2:$B$5,MATCH(F29,Lookups!$A$2:$A$5,0)),"") | I29: Not started | L29: GET /api/github/account → {connected, username, avatarUrl, connectedAt, lastSyncAt, syncStatus}. DELETE /api/github/disconnect also calls GitHub's grant-revocation API (best effort) and evicts caches. | M29: Expected Outcome delivered and all Verification checks pass. | N29: integration tests (WireMock for GitHub).
A30: M3-04 | B30: M3 - GitHub connect, repos & PRs | C30: Asynchronous sync + manual resync | D30: BE | E30: P0 | F30: M | G30: =IFERROR(INDEX(Lookups!$B$2:$B$5,MATCH(F30,Lookups!$A$2:$A$5,0)),"") | I30: Not started | L30: the callback only stores the account and enqueues a sync (@Async on a virtual-thread executor, or the D-12 job mechanism). Each repo is synced in its own transaction. POST /api/github/sync (rate-limited, 1 per minute). Sync status is stored on the account. RestClient connect/read timeouts are set. GitHub 403/429 rate-limit headers are respected. | M30: Expected Outcome delivered and all Verification checks pass. | N30: an integration test where the callback returns promptly with a slow WireMock; sync completes asynchronously and status moves to COMPLETED.
A31: M3-05 | B31: M3 - GitHub connect, repos & PRs | C31: Paged "my repositories" API | D31: BE | E31: P0 | F31: S | G31: =IFERROR(INDEX(Lookups!$B$2:$B$5,MATCH(F31,Lookups!$A$2:$A$5,0)),"") | H31: M1-01, M1-02. | I31: Not started | L31: GET /api/github/repositories?page&size&q&reviewEnabled → Page<RepositoryResponse> for the current user, sorted by name. | M31: Expected Outcome delivered and all Verification checks pass. | N31: MockMvc with paging and filter cases.
A32: M3-06 | B32: M3 - GitHub connect, repos & PRs | C32: Per-repository review toggle | D32: BE | E32: P1 | F32: S | G32: =IFERROR(INDEX(Lookups!$B$2:$B$5,MATCH(F32,Lookups!$A$2:$A$5,0)),"") | I32: Not started | L32: migration adds review_enabled boolean default false (plus auto_review, post_comments per D-13). PATCH /api/github/repositories/{id}. | M32: Expected Outcome delivered and all Verification checks pass. | N32: MockMvc + ownership test.
A33: M3-07 | B33: M3 - GitHub connect, repos & PRs | C33: Scoped, paged PR APIs | D33: BE | E33: P0 | F33: M | G33: =IFERROR(INDEX(Lookups!$B$2:$B$5,MATCH(F33,Lookups!$A$2:$A$5,0)),"") | I33: Not started | L33: GET /api/github/repositories/{repoId}/pull-requests?state&page&size, GET /api/github/pull-requests/{id} (detail includes the latest review status once M4 lands). Old PR routes are removed or redirected. | M33: Expected Outcome delivered and all Verification checks pass. | N33: MockMvc + ownership tests.
A34: M3-08 | B34: M3 - GitHub connect, repos & PRs | C34: Connect GitHub UX | D34: FE | E34: P0 | F34: M | G34: =IFERROR(INDEX(Lookups!$B$2:$B$5,MATCH(F34,Lookups!$A$2:$A$5,0)),"") | I34: Not started | L34: onboarding card on the dashboard when not connected. "Connect GitHub" calls authorize and redirects the browser. The /github/callback page reads status and shows success/error, polling sync status. The settings section shows the connected account, Resync, and Disconnect (with confirm dialog). | M34: Expected Outcome delivered and all Verification checks pass. | N34: RTL + MSW; manual run with a real GitHub test account. | O34: M3-01..M3-04.
A35: M3-09 | B35: M3 - GitHub connect, repos & PRs | C35: Repositories list and detail | D35: FE | E35: P0 | F35: M | G35: =IFERROR(INDEX(Lookups!$B$2:$B$5,MATCH(F35,Lookups!$A$2:$A$5,0)),"") | I35: Not started | L35: /repositories table/cards with search, filter (enabled, language), pagination, badges (private, fork, archived), and an enable-review toggle (optimistic update). /repositories/:id header with tabs: Pull Requests · Index (M6) · Settings. | M35: Expected Outcome delivered and all Verification checks pass. | N35: RTL; manual E2E.
A36: M3-10 | B36: M3 - GitHub connect, repos & PRs | C36: Pull request list and detail | D36: FE | E36: P0 | F36: M | G36: =IFERROR(INDEX(Lookups!$B$2:$B$5,MATCH(F36,Lookups!$A$2:$A$5,0)),"") | I36: Not started | L36: PR tab with state filter (Open/Closed/Merged) and pagination. /repositories/:id/pulls/:prId shows title, author, branches, links to GitHub, and the review panel placeholder (filled by M4-11). | M36: Expected Outcome delivered and all Verification checks pass. | N36: RTL; manual E2E.
A37: M4-01 | B37: M4 - AI review engine | C37: Review schema | D37: BE | E37: P0 | F37: M | G37: =IFERROR(INDEX(Lookups!$B$2:$B$5,MATCH(F37,Lookups!$A$2:$A$5,0)),"") | I37: Not started | L37: migration: pull_requests + head_sha, base_sha, additions, deletions, changed_files. reviews (pr_id, head_sha, status, trigger, provider, model, summary, files_reviewed, tokens_in/out, error, started/completed_at, requested_by). review_findings (review_id, file_path, start_line, end_line, side, severity, category, cwe, title, description, recommendation, confidence, source LLM/RULE, status OPEN/DISMISSED, github_comment_id). Indexes on (pr_id, created_at) and (review_id). Entities + repositories. | M37: Expected Outcome delivered and all Verification checks pass. | N37: Flyway migrates on an empty DB and on a DB at V2; Hibernate validates.
A38: M4-02 | B38: M4 - AI review engine | C38: Fetch PR files and patches | D38: BE | E38: P0 | F38: M | G38: =IFERROR(INDEX(Lookups!$B$2:$B$5,MATCH(F38,Lookups!$A$2:$A$5,0)),"") | I38: Not started | L38: GitHubApiClient.getPullRequestFiles(owner, repo, number) (paged, 3000-file cap) and getPullRequest (for SHAs). GET /api/github/pull-requests/{id}/files → [{filename,status,additions,deletions,patch}] (cached by head SHA). | M38: Expected Outcome delivered and all Verification checks pass. | N38: WireMock tests (including a binary file with no patch and a truncated patch).
A39: M4-03 | B39: M4 - AI review engine | C39: Diff parser and chunker | D39: BE | E39: P0 | F39: L | G39: =IFERROR(INDEX(Lookups!$B$2:$B$5,MATCH(F39,Lookups!$A$2:$A$5,0)),"") | I39: Not started | L39: parse unified-diff hunks into added/context lines with new-file line numbers. Group into token-bounded chunks per file. Skip lockfiles, generated, vendored, and binary files. | M39: Expected Outcome delivered and all Verification checks pass. | N39: pure unit tests with fixture diffs (renames, deletions, multi-hunk, CRLF).
A40: M4-04 | B40: M4 - AI review engine | C40: Prompt v2 + structured-output validation | D40: BE | E40: P0 | F40: M | G40: =IFERROR(INDEX(Lookups!$B$2:$B$5,MATCH(F40,Lookups!$A$2:$A$5,0)),"") | I40: Not started | L40: prompts/pr-review.st asks for findings with file, startLine, endLine, severity, category, cwe?, confidence, and treats the code as untrusted (prompt-injection guard). Output goes through Spring AI BeanOutputConverter. Findings are validated (line inside the diff, enum values) and invalid ones dropped and logged. Mock provider returns deterministic findings anchored to the real diff lines. | M40: Expected Outcome delivered and all Verification checks pass. | N40: unit tests over provider output fixtures (valid, malformed JSON, out-of-range lines).
...

Sheet Decisions
A1: ID | B1: Decision | C1: Recommendation | D1: Needs Approval | E1: Status | F1: Your Decision | G1: Affects Tasks
A2: D-01 | B2: Leaked secrets & Git history | C2: Rotate + remove from HEAD (a); optionally rewrite history later | D2: Yes | E2: Decided | F2: Option (a) for now (2026-10-21) | G2: M0-01, M0-05
A3: D-02 | B3: GitHub App vs OAuth App | C3: GitHub App | D3: Yes | E3: Open | G3: M3-01, M5-01, M5-04
A4: D-03 | B4: LLM provider & spend | C4: Keep mock default; pick one real provider for M4-15 with a spend cap | D4: Yes (paid) | E4: Open | G4: M4-04, M4-07, M4-15
A5: D-04 | B5: Frontend location | C5: frontend/ folder in this repo (monorepo) | D5: No | E5: Open | G5: M2-03
A6: D-05 | B6: Browser session strategy | C6: Bearer JWT in memory + sessionStorage for MVP; refresh cookie later | D6: No | E6: Open | G6: M2-04, M7-06
A7: D-06 | B7: Embeddings & vector store | C7: Local ONNX embeddings + pgvector, model loaded from URI | D7: No | E7: Open | G7: M0-05, M6-*
A8: D-07 | B8: AWS footprint & cost | C8: Check Billing now; ECS Fargate + RDS + S3/CloudFront at M8 | D8: Yes (cost) | E8: Open | G8: M8-*
A9: D-08 | B9: Keep S3? | C9: Remove test controller; no S3 until a real need | D9: No | E9: Open | G9: M1-08
A10: D-09 | B10: Spring Boot version | C10: Latest 3.5.x patch now; Boot 4 upgrade after M4 | D10: No | E10: Open | G10: M0, post-M4
A11: D-10 | B11: Docker runtime on Mac | C11: Docker Desktop | D11: No | E11: Decided | F11: Docker Desktop | G11: M0-03, M0-07
A12: D-11 | B12: Frontend stack | C12: Vite + React + TS, React Router, TanStack Query, Tailwind + shadcn/ui | D12: No | E12: Open | G12: M2-03..M2-05
A13: D-12 | B13: Background jobs | C13: DB job table + @Async on virtual threads | D13: No | E13: Open | G13: M3-04, M4-05, M6-04
A14: D-13 | B14: Review defaults | C14: Opt-in per repo, auto-review on, comments off, threshold MEDIUM | D14: No | E14: Open | G14: M3-06, M5-05
A15: IDE | B15: Editor | C15: IntelliJ IDEA (free) for backend, VS Code for frontend | D15: No | E15: Decided | F15: IntelliJ IDEA downloaded | G15: -

Sheet Completed (pre-restart)
A1: ID | B1: Item | C1: Evidence | D1: Caveat
A2: C-01 | B2: Maven project, Spring Boot 3.5.6, Java 21, layered packages | C2: pom.xml | D2: Compile not yet verified
A3: C-02 | B3: Registration with BCrypt + validation | C3: UserServiceImpl.register, RegisterRequest | D3: Returns plain text
A4: C-03 | B4: Login issuing JWT with jti and expiry | C4: JwtService.generateToken | D4: Secret leaked → rotate (M0-01)
A5: C-04 | B5: Logout via Redis jti blacklist | C5: AuthController.logout, JwtBlacklistServiceImpl | D5: Crashes on malformed token (M1-03)
A6: C-05 | B6: Profile read/update, change password | C6: ProfileController, UserServiceImpl | D6: 500 on missing user (M1-04)
A7: C-06 | B7: Role-based method security | C7: SecurityConfig @EnableMethodSecurity, AdminController | D7: —
A8: C-07 | B8: GitHub OAuth state (HMAC, Redis, single-use, 10 min) | C8: GitHubOAuthStateServiceImpl | D8: —
A9: C-08 | B9: GitHub API client: user, repos, PRs (paged) | C9: GitHubApiClientImpl | D9: No timeouts or rate-limit handling
A10: C-09 | B10: Repo + PR upsert synchronization | C10: GitHubRepositoryServiceImpl, PullRequestServiceImpl | D10: Sync in request thread; PR cache bug
A11: C-10 | B11: Redis wrapper + repository cache | C11: RedisServiceImpl, GitHubCacheServiceImpl | D11: —
A12: C-11 | B12: AI provider abstraction, mock + OpenAI, JSON prompt | C12: AIProviderConfig, prompts/code-review.st | D12: Snippet-only, unpersisted
... A14: C-13 | B14: Multi-stage non-root Dockerfile | C14: Dockerfile | D14: Bundles the 90 MB model
A16: Completed by code review only - not runtime-verified (see PROJECT_AUDIT.md).

Sheet Lookups
A1: Effort | B1: Est. Hours | C1: Meaning | E1: Status values | G1: Priority
A2: S | B2: 2 | C2: Up to ~2 hours | E2: Not started | G2: P0 | H2: Blocks the milestone exit
A3: M | B3: 4 | C3: About half a day | E3: In progress | G3: P1 | H3: Needed, not blocking
A4: L | B4: 8 | C4: About one day | E4: Blocked | G4: P2 | H4: Nice to have / can slip
A5: XL | B5: 16 | C5: Two+ days - split before starting | E5: Done
A8: Hour values (blue) are planning assumptions from TASK_BACKLOG.md effort sizes - edit them to re-scale every estimate.
